Workbook

Sheet Sistemas
A1: País | B1: Código | C1: Região | D1: Sistema de pagamento | E1: Descrição | F1: Site oficial | G1: Detalhes completos | H1: Página no Atlas
A2: Afghanistan | B2: AF | D2: AfPay Card | E2: Domestic debit card scheme on APS network | F2: https://dap.gov.af/afpay | G2: AfPay is Afghanistan’s national debit card scheme issued by local banks and routed via the APS switch (https://dab.gov.af/afghanistan-payments-system-department#:~:text=1,MFIs) (https://www.ghazanfarbank.com/af-pay_debit_card#:~:text=Af). AfPay cards allow customers to access their bank accounts through any ATM in the country and make POS purchases at participating merchants (https://www.ghazanfarbank.com/af-pay_debit_card#:~:text=AF,Below%20are%20few%20features) (https://www.ghazanfarbank.com/af-pay_debit_card#:~:text=,Balance%20Inquiry). The scheme aims to reduce reliance on cash by providing low-cost card services domestically. AfPay cards can be denominated in local Afghani or USD (https://www.ghazanfarbank.com/af-pay_debit_card#:~:text=,Balance%20Inquiry). Adoption is growing slowly – banks have issued AfPay cards to a subset of their clients, and features like balance inquiry, PIN change and low fees are designed to encourage usage (https://www.ghazanfarbank.com/af-pay_debit_card#:~:text=AF,Below%20are%20few%20features) (https://www.ghazanfarbank.com/af-pay_debit_card#:~:text=,Balance%20Inquiry). However, usage is mostly for ATM cash withdrawals, and overall card payment volumes remain low. | H2: https://thepaymentsatlas.com/country/AF
A3: Afghanistan | B3: AF | D3: HesabPay Platform | E3: Interoperable digital wallet on blockchain rails | F3: https://hesab.af | G3: **HesabPay** is a digital wallet platform in Afghanistan that achieved interoperability by working with APS, banks and telcos (https://www.undp.org/sites/g/files/zskgke326/files/2023-06/interoperability_of_fsps_afghanistan_undp-uncdf.pdf#:~:text=solution%20already%20reaching%20400%2C000%20people,Number%20of%20ATMs%20in%20Afghanistan). Built with blockchain technology, HesabPay enables users to link their bank accounts and mobile numbers to send and receive money instantly via mobile app or QR code. By 2021 it reached around 400,000 users (https://www.undp.org/sites/g/files/zskgke326/files/2023-06/interoperability_of_fsps_afghanistan_undp-uncdf.pdf#:~:text=solution%20already%20reaching%20400%2C000%20people,Number%20of%20ATMs%20in%20Afghanistan). HesabPay transactions are cleared through APS so funds can move between any bank or wallet on the network. It was the first wallet to connect all major banks and mobile operators, offering Afghans a modern P2P payment option in local currency. While promising, its expansion depends on smartphone penetration and the broader economic stability. Still, it represents a growing fintech approach to bypass traditional cash channels. | H3: https://thepaymentsatlas.com/country/AF
A4: Afghanistan | B4: AF | D4: Mobile Money Services (M-Paisa, mHawala, etc.) | E4: Mobile wallet services for transfers, top-ups and bill payments | F4: https://dab.gov.af/sites/default/files/2020-11/MobileMoneyReport.pdf | G4: Several telcos operate mobile money schemes in Afghanistan under central bank license (https://www.undp.org/sites/g/files/zskgke326/files/2023-06/interoperability_of_fsps_afghanistan_undp-uncdf.pdf#:~:text=Today%2C%20there%20are%20four%20mobile,ups). Notably, Roshan’s **M-Paisa** (launched 2008) was one of the first, followed by Etisalat’s **mHawala**, MTN’s **MoMo**, and Afghan Wireless’s **My Money** (https://www.undp.org/sites/g/files/zskgke326/files/2023-06/interoperability_of_fsps_afghanistan_undp-uncdf.pdf#:~:text=Today%2C%20there%20are%20four%20mobile,ups). These services allow users to transfer funds, pay utility bills, top-up phones, and receive salaries via mobile phone without a traditional bank account. Interoperability across these wallets was limited until recently. By 2021, fewer than 1% of Afghans used mobile money, reflecting limited agent networks and trust (https://www.undp.org/sites/g/files/zskgke326/files/2023-06/interoperability_of_fsps_afghanistan_undp-uncdf.pdf#:~:text=%28M,took%20place%20in%20August%202021) (https://www.undp.org/sites/g/files/zskgke326/files/2023-06/interoperability_of_fsps_afghanistan_undp-uncdf.pdf#:~:text=common%20use%20cases%20of%20mobile,SERVICES%20PROVIDERS%20NUMBER%20OF%20AGENTS). After 2021, usage faced further challenges but initiatives to integrate mobile wallets with APS were underway to enable wallet-to-bank transfers (https://www.hks.harvard.edu/sites/default/files/centers/mrcbg/209_AWP_final.pdf#:~:text=circumstances%2C%20DAB%20was%20able%20to,mobile%20wallets%20and%20bank%20accounts). Mobile money in Afghanistan remains nascent but is seen as a tool for financial inclusion in a largely unbanked population. | H4: https://thepaymentsatlas.com/country/AF
A5: Afghanistan | B5: AF | D5: Automated Clearing House (ACH) | E5: Electronic clearing for low-value interbank payments | F5: https://dab.gov.af/afghanistan-payments-system-department | G5: Afghanistan’s ACH was implemented alongside the RTGS in 2020 (https://www.hks.harvard.edu/sites/default/files/centers/mrcbg/209_AWP_final.pdf#:~:text=To%20begin%2C%20we%20review%20Afghanistan%E2%80%99s,mobile%20wallets%2C%20as%20well%20as) to clear retail payments (such as checks, salary payments, and small fund transfers) among banks. It operates in batch mode, aggregating low-value payment instructions and clearing them at scheduled intervals. The ACH improves efficiency for routine transactions compared to manual clearing. However, given low levels of electronic payments, transaction volumes through the ACH are still modest. It provides a foundation for modernizing retail payments, but cash and informal methods remain predominant. | H5: https://thepaymentsatlas.com/country/AF
A6: Afghanistan | B6: AF | D6: Afghanistan Transfers System (RTGS) | E6: Operated by Da Afghanistan Bank (DAB). Launched December 2020 with World Bank support to settle large-value and urgent payments in afghanis. Connected to APS for retail net positions. | F6: https://dab.gov.af/Payments-Department | H6: https://thepaymentsatlas.com/country/AF
A7: Afghanistan | B7: AF | D7: Afghanistan Payments System (APS) – National Switch | E7: General Directorate of DAB. Provides switching, clearing and daily multilateral settlement via the RTGS. Hosts AfPay domestic card scheme and *246# USSD service. | F7: https://aps.gov.af | H7: https://thepaymentsatlas.com/country/AF
A8: Afghanistan | B8: AF | D8: AfPay Domestic Card Scheme | E8: Provides interoperable ATM/POS access across 360+ ATMs and 2 000 POS devices. PIN-based mag-stripe with EMV migration roadmap. | F8: https://aps.gov.af/af-pay/ | H8: https://thepaymentsatlas.com/country/AF
A9: Afghanistan | B9: AF | D9: Afghanistan Payments System (APS) | E9: National e-payment switch for cards, ATMs, POS and mobile | F9: http://aps.gov.af | G9: APS is the national retail payment switch, established under Da Afghanistan Bank to interconnect banks, ATMs, POS terminals and mobile money operators (https://www.ariananews.af/launch-of-the-afghan-national-payment-switch-opening-the-gate-to-the-global-financial-network/#:~:text=Wasdam%3A%20Afghanistan%20Payments%20Systems%20,Card%2FMobile%20Payment%20Switch%20in%20Afghanistan) (https://www.ariananews.af/launch-of-the-afghan-national-payment-switch-opening-the-gate-to-the-global-financial-network/#:~:text=This%20National%20Switch%20will%20provide,APS%E2%80%99%20processing%20and%20telecommunications%20partners). APS provides switching and clearing for card transactions (ATM withdrawals and POS purchases) and facilitates interoperability among banks. It also connects to international card networks to enable usage of global cards domestically (https://dab.gov.af/afghanistan-payments-system-department#:~:text=Afghanistan%20Payments%20System%20,banking%20offering%20in%20the%20country) (https://dab.gov.af/afghanistan-payments-system-department#:~:text=Act%20as%20National%20Switch%20of,institution%20and%20international%20card%20schemes). APS launched the domestic card scheme “AfPay” and links bank accounts with mobile wallets to promote cashless payments. Despite this infrastructure, card usage remains limited due to cash dominance – only about 1.3 million cardholders exist and ~2,000 POS terminals nationwide (https://www.undp.org/sites/g/files/zskgke326/files/2023-06/interoperability_of_fsps_afghanistan_undp-uncdf.pdf#:~:text=solution%20already%20reaching%20400%2C000%20people,Number%20of%20ATMs%20in%20Afghanistan) (https://www.undp.org/sites/g/files/zskgke326/files/2023-06/interoperability_of_fsps_afghanistan_undp-uncdf.pdf#:~:text=code,89%20New%20Kabul%20Bank%2042). APS is pivotal for modern retail payments, but its potential is constrained by low banking penetration and infrastructure challenges. | H9: https://thepaymentsatlas.com/country/AF
A10: Afghanistan | B10: AF | D10: Afghanistan Interbank Payment System (AIPS) | E10: National interbank real-time gross settlement system | F10: https://dab.gov.af/afghanistan-payments-system-department | G10: AIPS is Afghanistan’s RTGS (Real-Time Gross Settlement) system operated by Da Afghanistan Bank, launched in late 2020 to enable electronic interbank fund transfers (https://www.hks.harvard.edu/sites/default/files/centers/mrcbg/209_AWP_final.pdf#:~:text=To%20begin%2C%20we%20review%20Afghanistan%E2%80%99s,mobile%20wallets%2C%20as%20well%20as). It processes large-value payments between banks in real time and with finality. AIPS is critical for interbank settlements but overall usage remains limited by Afghanistan’s largely cash-based economy (https://www.fintechfutures.com/paytech/bpc-s-smartvista-powers-afghanistan-s-national-payment-system#:~:text=Angelo%20Bertini%2C%20managing%20director%20of,resulted%20in%20%E2%80%9Climited%E2%80%9D%20cards%20usage). It handles mainly credit transfers between financial institutions and government, providing a backbone for the formal banking sector’s payments. | H10: https://thepaymentsatlas.com/country/AF
A11: Albania | B11: AL | D11: ArTelco (Mobile Money/E-money services) | E11: Emerging mobile payment and e-wallet providers | F11: https://www.easypay.al | G11: Albania’s mobile payment ecosystem is in early stages. Private fintechs like **EasyPay** (an e-money issuer) provide digital wallets for P2P transfers, bill pay, and mobile top-ups (https://www.iamtn.org/companies/easypay#:~:text=EasyPay%20,time) (https://albaniatech.org/show_cases/easypay-the-leading-digital-payment-platform-in-albania/#:~:text=EasyPay%3A%20The%20leading%20digital%20payment,time%20payments). EasyPay, launched 2010, has built a network of 400+ agents and processes real-time payments in ALL (https://albaniatech.org/show_cases/easypay-the-leading-digital-payment-platform-in-albania/#:~:text=payment%20platform%20that%20allows%20people,time%20payments). Banks also offer mobile banking apps, but dedicated mobile money by telcos is not widespread. The regulatory framework was updated in 2020 to enable more non-bank payment service providers (https://www.bis.org/review/r241206a.htm#:~:text=Thus%2C%20in%20November%202024%2C%20upon,conduct%20the%20open%20banking%20activity) (https://www.bis.org/review/r241206a.htm#:~:text=I%20would%20like%20to%20point,other%20financial%20services%20for%20clients). As of 2023, ~78% of Albanians have bank accounts (https://monitor.al/en/Financial-inclusion-has-increased--78%25-of-Albanians-have-a-payment-account/#:~:text=Sejko%3A%20Financial%20inclusion%20has%20increased%2C,avoidance%20of%20long%20queues), so mobile wallets complement bank services. Adoption of e-wallets is moderate and growing, with an estimated 1–2 hundred thousand active users. The central bank encourages innovation (open banking licenses were issued in 2024) to expand digital payments (https://www.bis.org/review/r241206a.htm#:~:text=As%20you%20are%20aware%2C%20after,open%20banking%20functional%20in%20practice) (https://www.bis.org/review/r241206a.htm#:~:text=Thus%2C%20in%20November%202024%2C%20upon,conduct%20the%20open%20banking%20activity), suggesting Albania’s mobile and instant payments will grow in coming years. | H11: https://thepaymentsatlas.com/country/AL
A12: Albania | B12: AL | D12: Banka e Shqipërisë RTGS | E12: Real-time settlement | F12: https://www.bankofalbania.org | H12: https://thepaymentsatlas.com/country/AL
A13: Albania | B13: AL | D13: Visa/Mastercard | E13: Card payments | F13: https://www.visa.com/ | H13: https://thepaymentsatlas.com/country/AL
A14: Albania | B14: AL | D14: AIPS Euro | E14: Domestic euro RTGS for Albania | F14: https://www.bankofalbania.org/Payments/AIPS_EURO | G14: AIPS Euro is a euro-denominated RTGS introduced by Bank of Albania in 2022 to settle domestic customer payments in Euro (https://www.bankofalbania.org/Payments/Payment_systems_statistics/#:~:text=,68). It allows Albanian banks to transfer euros in-country in real time without using correspondent banks abroad. By Q1 2023, AIPS Euro processed ~81,000 transfers totaling €1.3 billion (https://scantv.al/english/lajme/shqiperia/rreth-13-mld-pagesa-ne-euro-me-aips-bsh-ne-tremujorin-e-pare-20--i23393#:~:text=Around%201,system%2C%20which%20reached%20a). The system significantly lowers cost and time for euro payments – fees dropped ~5× and same-day transfer is standard (https://www.bis.org/review/r241206a.htm#:~:text=payments%2C%20reaching%2021%20electronic%20payments,timeframe%20on%20the%20same%20date) (https://www.bis.org/review/r241206a.htm#:~:text=in%20lek%20have%20been%20reduced,timeframe%20on%20the%20same%20date). The inclusion of Albania in the SEPA schemes (since late 2024) will further integrate AIPS Euro with European payments (https://www.bis.org/review/r241206a.htm#:~:text=First%2C%20as%20you%20already%20know%2C,towards%20membership%20in%20the%20SEPA) (https://www.bis.org/review/r241206a.htm#:~:text=jurisdiction%2C%20the%20concrete%20economic%20benefits,contribution%20to%20the%20Albanian%20economy). Adoption is growing quickly as businesses and individuals increasingly send euros domestically, saving an estimated €90 million in fees since launch (https://www.bis.org/review/r241206a.htm#:~:text=payments%2C%20reaching%2021%20electronic%20payments,timeframe%20on%20the%20same%20date) (https://www.bis.org/review/r241206a.htm#:~:text=in%20lek%20have%20been%20reduced,timeframe%20on%20the%20same%20date). | H14: https://thepaymentsatlas.com/country/AL
A15: Albania | B15: AL | D15: Card Payment Schemes (Visa, MasterCard & ArCa) | E15: Card networks used in Albania for ATM and POS payments | F15: https://www.bankofalbania.org/Payments/Payment_instruments | G15: Albanian banks issue mainly international card brands (Visa, MasterCard) for debit and credit. There is no separate domestic-only card scheme; however, all banks are connected via common card processing arrangements. As of end 2021, over **11.6 million** payment cards were in circulation in Albania (http://news.radioalgerie.dz/fr/node/4439#:~:text=Cartes%20interbancaires) (http://news.radioalgerie.dz/fr/node/4439#:~:text=,671%20cartes) – this includes 1.53 million Visa/Mastercard debit cards, ~83k corporate cards, 1.16 million savings cards, and 8.84 million Albanian Post’s card accounts (http://news.radioalgerie.dz/fr/node/4439#:~:text=Ce%20chiffre%20est%20r%C3%A9parti%20comme,suit). Card usage is rising but historically most card transactions were cash withdrawals: in 2011, 96% of card transactions were ATM withdrawals (https://www.tiranatimes.com/boa-albanias-economy-96-cash-based_113020/#:~:text=The%20latest%20central%20bank%20report,at%20the%20end%20of%202010) (https://www.tiranatimes.com/boa-albanias-economy-96-cash-based_113020/#:~:text=stability%20for%20the%20first%20half,at%20only%20a%20mere%2028%2C635). By 2021, card payments at POS and online reached ~10 million transactions, while ATM withdrawals were ~10× higher (http://news.radioalgerie.dz/fr/node/4439#:~:text=,035%2C60%20dinars) (http://news.radioalgerie.dz/fr/node/4439#:~:text=,789). Adoption of cards is growing as POS infrastructure expands (4,700+ POS devices by 2011 (https://www.tiranatimes.com/boa-albanias-economy-96-cash-based_113020/#:~:text=Almost%20all%20commercial%20banks%20operating,1%20percent%20to%204%2C729)). The Bank of Albania and banks promote card usage to reduce cash in the economy (still ~96% cash-based as of 2011 (https://www.tiranatimes.com/boa-albanias-economy-96-cash-based_113020/#:~:text=The%20latest%20central%20bank%20report,at%20the%20end%20of%202010)). | H15: https://thepaymentsatlas.com/country/AL
A16: Albania | B16: AL | D16: AIPS (Albanian Interbank Payment System) | E16: AIPS is Albania’s RTGS operated by the Bank of Albania, processing large-value and urgent interbank payments in lek. All commercial banks participate in AIPS . Transactions are settled individually and irrevocably in real time. In 2022 AIPS settled ~154,000 transactions totaling 13,020 billion ALL (about 5× GDP) . AIPS has dramatically improved efficiency and safety of high-value transfers since its launch in 2004. An Euro-denominated counterpart, **AIPS Euro**, launched in 2022 to settle domestic euro payments, saving customers fees by avoiding correspondent banking . AIPS forms the backbone of Albania’s payment infrastructure, with very high adoption among banks and robust growth as the economy digitizes. | F16: https://www.bankofalbania.org/Payments/AIPS | G16: AIPS is Albania’s RTGS operated by the Bank of Albania, processing large-value and urgent interbank payments in lek. All commercial banks participate in AIPS (https://www.bankofalbania.org/Payments/Payment_systems_statistics/#:~:text=Payment%20System) (https://www.bankofalbania.org/Payments/Payment_systems_statistics/#:~:text=,About%20the%20NPSC). Transactions are settled individually and irrevocably in real time. In 2022 AIPS settled ~154,000 transactions totaling 13,020 billion ALL (about 5× GDP) (https://www.bankofalbania.org/rc/doc/Annual_Report_2022_ENG_FINAL_24811.pdf#:~:text=,of%20ALL%2013%2C020%20billion%2C). AIPS has dramatically improved efficiency and safety of high-value transfers since its launch in 2004. An Euro-denominated counterpart, **AIPS Euro**, launched in 2022 to settle domestic euro payments, saving customers fees by avoiding correspondent banking (https://www.bis.org/review/r241206a.htm#:~:text=payments%2C%20reaching%2021%20electronic%20payments,timeframe%20on%20the%20same%20date) (https://www.bis.org/review/r241206a.htm#:~:text=payments%20in%202015,timeframe%20on%20the%20same%20date). AIPS forms the backbone of Albania’s payment infrastructure, with very high adoption among banks and robust growth as the economy digitizes. | H16: https://thepaymentsatlas.com/country/AL
A17: Albania | B17: AL | D17: AECH (Albanian Electronic Clearing House) | E17: AECH is Albania’s clearing system for low-value, non-urgent interbank payments (e.g. ACH credit transfers, direct debits). Banks send files of retail payment instructions to AECH, which nets multilateral positions at scheduled sessions . The Bank of Albania operates AECH alongside AIPS . AECH has enabled more efficient clearing of checks and small transfers, with transaction volumes in the millions per year. For example, in 2011 AECH cleared ~17 million transactions (10,582 billion ALL) , and volumes have grown steadily as electronic payments increase. AECH reduces costs for banks and customers through batch netting. While cash usage in Albania is still high, AECH is increasingly important for payroll, bill payments and everyday transfers. | F17: https://www.bankofalbania.org/Payments/AECH | G17: AECH is Albania’s clearing system for low-value, non-urgent interbank payments (e.g. ACH credit transfers, direct debits). Banks send files of retail payment instructions to AECH, which nets multilateral positions at scheduled sessions (https://www.tiranatimes.com/boa-albanias-economy-96-cash-based_113020/#:~:text=functioning%20of%20the%20Albanian%20Interbank,customers%20and%20the%20payment%20service). The Bank of Albania operates AECH alongside AIPS (https://www.bankofalbania.org/Payments/Payment_systems_statistics/#:~:text=Payment%20System). AECH has enabled more efficient clearing of checks and small transfers, with transaction volumes in the millions per year. For example, in 2011 AECH cleared ~17 million transactions (10,582 billion ALL) (https://fr.scribd.com/document/705902882/Les-Moyens-de-Paiement-Et-La-Monetique-en-Algerie-Bejaya#:~:text=L%E2%80%99ann%C3%A9e%202011%2C%20est%20caract%C3%A9ris%C3%A9e%20par,de%20l%E2%80%99ann%C3%A9e%202013%2C%20est%20de) (https://fr.scribd.com/document/705902882/Les-Moyens-de-Paiement-Et-La-Monetique-en-Algerie-Bejaya#:~:text=syst%C3%A8me%20RTGS%20avec%20un%20montant,de%20l%E2%80%99ann%C3%A9e%202013%2C%20est%20de), and volumes have grown steadily as electronic payments increase. AECH reduces costs for banks and customers through batch netting. While cash usage in Albania is still high, AECH is increasingly important for payroll, bill payments and everyday transfers. | H17: https://thepaymentsatlas.com/country/AL
A18: Algeria | B18: DZ | D18: CIB (Carte Interbancaire) | E18: Domestic interbank card network for ATMs/POS | F18: https://www.satim.dz | G18: CIB is Algeria’s national interbank card scheme, managed by **SATIM** (the national interbank card switch). Banks issue **CIB debit cards** to account holders, which can be used across all ATMs and POS terminals in the country (https://www.aps.dz/economie/135098-e-paiement-hausse-de-20-du-nombre-des-cartes-interbancaires-en-2021#:~:text=hausse%20de%2020,cartes%20Epargne%20est%20de). CIB cards carry the “CIB” logo and allow cash withdrawals, balance inquiries, and local purchases. As of 2023 there were over **4 million** CIB cards in circulation (https://lapatrienews.dz/e-paiement-plus-de-19-millions-de-cartes-electronique-en-circulation/#:~:text=E,sont%20des%20cartes%20d%27Alg%C3%A9rie%20Poste) (https://www.horizons.dz/?p=163563#:~:text=Les%20TPE%20et%20le%20mobile,Le%20nombre). The ATM/POS network under CIB is branded **“MULTI-CIB”** or **“MULTICAISSE”** in some contexts (through GIE Monétique). Card adoption has grown ~20% annually; in 2021, 1.53 million personal CIB cards were active (plus ~83k corporate and 1.16 million savings-linked cards) (http://news.radioalgerie.dz/fr/node/4439#:~:text=Ce%20chiffre%20est%20r%C3%A9parti%20comme,suit). These cards handle tens of millions of ATM withdrawals per year and an increasing number of POS payments. However, historically Algerians used cards mostly for cash – e.g. in 2021 cardholders made 87.7 million ATM withdrawals versus only ~2.15 million POS transactions (http://news.radioalgerie.dz/fr/node/4439#:~:text=,789%20transactions%20valides%20%28%2B50%2C14) (http://news.radioalgerie.dz/fr/node/4439#:~:text=,par%20rapport%20%C3%A0%202020). The government and banks are expanding POS acceptance and incentivizing digital payments, so CIB card usage for purchases is rising. CIB is fully EMV-compliant and coexists with international card brands (Visa, MasterCard) on dual-network cards. | H18: https://thepaymentsatlas.com/country/DZ
A19: Algeria | B19: DZ | D19: Edahabia Card (Algérie Poste) | E19: Postal financial card for government and personal payments | F19: https://poste.dz | G19: **Edahabia** is a payment card issued by Algérie Poste for holders of postal accounts (CCP). It is used for withdrawing cash at postal ATMs, making POS purchases, and paying bills through Algeria Post’s network. Edahabia has massive reach: over **13.3 million** Edahabia cards were in circulation by 2023 (https://www.horizons.dz/?p=163563#:~:text=Les%20TPE%20et%20le%20mobile,Le%20nombre) – far exceeding bank-issued cards – as many government salaries, pensions, and social benefits are paid into postal accounts. Edahabia is EMV chip-enabled and can be used online and at any Algérie Poste or CIB network terminal. Algérie Poste also offers **BaridiMob**, a mobile app linked to Edahabia for digital payments. In the first 5 months of 2023, BaridiMob handled 13 million transactions (https://www.aps.dz/en/algeria/tag/Epayment#:~:text=Epayment%20,of%202023%2C%20the%20Minister) – many of these are Edahabia cardholders paying utilities, P2P transfers, etc. Edahabia’s adoption is very high, driving financial inclusion by giving millions of unbanked citizens electronic payment access. The volume of Edahabia transactions is growing rapidly, making it a key pillar of Algeria’s payments ecosystem. | H19: https://thepaymentsatlas.com/country/DZ
A20: Algeria | B20: DZ | D20: Carte Edahabia | E20: National payment card system | F20: https://www.bank-of-algeria.dz | H20: https://thepaymentsatlas.com/country/DZ
A21: Algeria | B21: DZ | D21: Mobile Payment | E21: Growing mobile money services | F21: https://www.djezzypay.dz | H21: https://thepaymentsatlas.com/country/DZ
A22: Algeria | B22: DZ | D22: SATIM National Switch & CIB Card | E22: Société d’Automatisation des Transactions Interbancaires et de Monétique (SATIM) links 18 banks; 3 868 ATMs and 45.9 m POS transactions Q1-2024. Instant person-to-person and QR merchant payments launched pilot June 2024. | F22: https://www.satim.dz | H22: https://thepaymentsatlas.com/country/DZ
A23: Algeria | B23: DZ | D23: ATCI (Algérie Télécompensation Interbancaire) | E23: Electronic clearing house for retail payments | F23: https://www.bank-of-algeria.dz | G23: ATCI is Algeria’s national electronic clearing system for retail payments (mass payments like checks, electronic transfers, direct debits and card payments) (https://fr.linkedin.com/posts/banque-d-alg%C3%A9rie_le-gouverneur-de-bank-of-algeria-%D8%A8%D9%86%D9%83-%D8%A7%D9%84%D8%AC%D8%B2%D8%A7%D8%A6%D8%B1-activity-6907646881338699776-ujIY#:~:text=Post%20de%20Bank%20of%20Algeria,des%20moyens%20de%20paiement). Banks send batches of payment instructions to ATCI, which calculates multilateral net positions and forwards the net balances to the RTGS for settlement (http://droit-afrique.com/upload/doc/algerie/Algerie-Reglement-2005-06-compensation-cheques.pdf#:~:text=Alg%C3%A9rie%20Compensation%20des%20ch%C3%A8ques%20et,r%C3%A8glements%20bruts%20en%20temps) (http://droit-afrique.com/upload/doc/algerie/Algerie-Reglement-2005-06-compensation-cheques.pdf#:~:text=,r%C3%A8glements%20bruts%20en%20temps). ATCI has greatly sped up clearing of cheques and other instruments. Usage is extensive: in 2013 ATCI processed about **19.47 million** payment transactions totaling DA 12,662 billion (https://fr.scribd.com/document/705902882/Les-Moyens-de-Paiement-Et-La-Monetique-en-Algerie-Bejaya#:~:text=Le%20nombre%20d%E2%80%99op%C3%A9ration%20effectu%C3%A9%20par,de%20l%E2%80%99ann%C3%A9e%202013%2C%20est%20de). This includes settlement of check clearing, automated transfers and card network settlements. ATCI operates with daily clearing cycles. It is jointly run by the central bank and banking sector. Adoption is high – all banks use ATCI for their retail payment exchange, making it the backbone for everyday non-cash transactions in Algeria’s economy. | H23: https://thepaymentsatlas.com/country/DZ
A24: Algeria | B24: DZ | D24: BaridiMob & BaridiPay | E24: Mobile payment app and QR service by Algeria Post | F24: https://www.poste.dz/BaridiMob | G24: BaridiMob is Algeria Post’s mobile wallet application that allows Edahabia cardholders to conduct digital transactions from their smartphone. Via BaridiMob, users can transfer money to others, pay bills, recharge phones, and view account balances (https://www.mpt.gov.dz/strengthen-financial-inclusion-and-widespread-of-the-e-payment/#:~:text=Strengthen%20Financial%20Inclusion%20and%20Widespread,apps%20in%20Algeria%20on). It has become Algeria’s most downloaded financial app. In early 2023, BaridiMob was processing over **2.6 million transactions per month** (https://www.aps.dz/en/algeria/tag/Epayment#:~:text=Epayment%20,of%202023%2C%20the%20Minister). In parallel, Algérie Poste launched **BaridiPay**, a QR code payment service integrated into BaridiMob that enables instant retail payments without a physical card (https://www.dzair-tube.dz/en/algerie-poste-launches-baridi-pay-mobile-payment-service-a-bold-step-toward-a-cashless-card-free-economy/#:~:text=tube,the%20need%20for%20bank). This is aimed at merchants and informal markets to further promote cashless payments. Together, BaridiMob/BaridiPay form a fast-growing digital payments ecosystem leveraging Algeria’s extensive postal network. Adoption is growing quickly (13 million e-payments via BaridiMob in Jan–May 2023 (https://www.aps.dz/en/algeria/tag/Epayment#:~:text=Epayment%20,of%202023%2C%20the%20Minister), nearly double year-on-year). These services significantly enhance the utility of Edahabia and drive the migration from cash to electronic payments in everyday transactions. | H24: https://thepaymentsatlas.com/country/DZ
A25: Algeria | B25: DZ | D25: Interbank Electronic Clearing System (ATCI / CCAA) | E25: Managed by Centre de Pré-compensation Interbancaire (CPI); dematerialised clearing replacing manual houses since 2006 with daily multilateral netting to ARTS. | F25: https://cpi.dz | H25: https://thepaymentsatlas.com/country/DZ
A26: Algeria | B26: DZ | D26: ARTS (Algeria Real-time Settlement System) | E26: Live since 2006; processes interbank and BoA operations in dinars with liquidity facilities. | F26: https://www.bank-of-algeria.dz | H26: https://thepaymentsatlas.com/country/DZ
A27: Algeria | B27: DZ | D27: ARTS (Algerian Real-Time Settlement system) | E27: RTGS system for large-value payments in Algeria | F27: https://www.bank-of-algeria.dz | G27: ARTS is Algeria’s RTGS system operated by the Bank of Algeria to settle high-value interbank payments in real time. In French it is the **Règlement Brut en Temps Réel** system. All major banks and the central bank participate. ARTS has significantly reduced systemic risk and settlement times for large transactions. For example, by 2013 the RTGS processed ~290,000 payments annually (https://fr.scribd.com/document/705902882/Les-Moyens-de-Paiement-Et-La-Monetique-en-Algerie-Bejaya#:~:text=Le%20nombre%20d%E2%80%99op%C3%A9ration%20effectu%C3%A9%20par,de%20l%E2%80%99ann%C3%A9e%202013%2C%20est%20de), with a total value of DA 358,000 billion (hundreds of trillions of dinars) (https://fr.scribd.com/document/705902882/Les-Moyens-de-Paiement-Et-La-Monetique-en-Algerie-Bejaya#:~:text=Le%20nombre%20d%E2%80%99op%C3%A9ration%20effectu%C3%A9%20par,de%20l%E2%80%99ann%C3%A9e%202013%2C%20est%20de). Transactions are final and irrevocable once settled in ARTS. The system typically handles government securities trades, interbank transfers, and other urgent payments. Adoption is very high among banks – ARTS is the primary channel for wholesale payments. The central bank is also connecting to the regional SADC-RTGS to facilitate cross-border settlements (https://pti.ao/bna-esclarece-ambito-da-integracao-do-kwanza-no-sistema-da-sadc/#:~:text=BNA%20esclarece%20%C3%A2mbito%20da%20integra%C3%A7%C3%A3o,pagamento%20angolanos%20ao%20sistema) (https://angolex.com/paginas/avisos/participacao-no-sistema-de-liquidacao-bruto-em-tempo-real-da-sadc-03a-2025a.html#:~:text=Aviso%20n,SPTR). Overall, ARTS is a cornerstone of Algeria’s modern payment infrastructure. | H27: https://thepaymentsatlas.com/country/DZ
A28: Andorra | B28: AD | D28: SEPA Credit Transfer (SCT) | E28: Euro credit transfers under SEPA scheme | F28: https://www.andorranbanking.ad/sepa | G28: Since March 2019, Andorra has been part of the Single Euro Payments Area (SEPA) (https://en.neofi-solutions.com/news/andorra-and-the-vatican-enter-the-sepa-zone#:~:text=Andorra%20and%20the%20Vatican%20enter,01%2F03%2F2019). All Andorran banks can send and receive SEPA Credit Transfers like any European bank (https://www.andorranbanking.ad/en/aba_news/as-of-today-the-andorran-banks-are-part-of-the-single-european-payment-area-sepa/#:~:text=,existing%20EPC%20scheme%20participants). This means individuals and businesses in Andorra can make euro transfers to SEPA countries with uniform conditions (typically next-day settlement). Andorran banks connect to SEPA clearing via partnerships (e.g., through Spanish clearinghouse Iberpay or EBA’s STEP2). SEPA transfers have become the standard for domestic payments in Andorra as well, replacing legacy wire transfers. Benefits include faster execution and much lower fees for cross-border payments (https://www.bis.org/review/r241206a.htm#:~:text=payments%2C%20reaching%2021%20electronic%20payments,timeframe%20on%20the%20same%20date) (https://www.bis.org/review/r241206a.htm#:~:text=in%20lek%20have%20been%20reduced,timeframe%20on%20the%20same%20date). Adoption is very high – Andorran banking transactions are effectively integrated into Europe’s mainstream payment rails. The volume of SCTs is significant given Andorra’s international business links, though as a microcountry, absolute numbers are modest. Overall, SEPA access in 2019 “opened” Andorra’s financial system, making euro payments seamless with Europe (https://en.andorraservices.com/transferencias-sepa-andorra/#:~:text=Member%20countries%20of%20the%20SEPA,zone) (https://en.andorraservices.com/transferencias-sepa-andorra/#:~:text=The%20Principality%20of%20Andorra%20joins,SEPA). | H28: https://thepaymentsatlas.com/country/AD
A29: Andorra | B29: AD | D29: SEPA Direct Debit (SDD) | E29: Euro direct debit scheme in Andorra | F29: https://www.andorranbanking.ad/sepa | G29: After joining SEPA, Andorran banks also adopted the SEPA Direct Debit Core and B2B schemes. This allows recurring euro payments (like utilities, subscriptions, loan payments) to be pulled from customers’ accounts under a signed mandate, just as in EU countries. Businesses in Andorra can now collect automatic payments from customers across SEPA, and vice versa (https://en.andorraservices.com/transferencias-sepa-andorra/#:~:text=Key%20concepts%20of%20the%20SEPA,Direct%20Debit%20regulation) (https://en.andorraservices.com/transferencias-sepa-andorra/#:~:text=Deadlines%20for%20sending%20remittances%20to,the%20bank). The legal framework was aligned with SEPA rules by 2021. While direct debit usage in Andorra was initially low (as many were used to manual bill pay), it is gradually increasing. Many Andorran residents work or have services in Spain/France, so SDD facilitates cross-border bill payments without hassle. Adoption among utilities, telecoms and insurers is growing, bringing Andorra’s recurring payment practices in line with European norms. With clear refund rights and standardized timings (e.g., D-1 submission) (https://en.andorraservices.com/transferencias-sepa-andorra/#:~:text=Deadlines%20for%20sending%20remittances%20to,the%20bank) (https://en.andorraservices.com/transferencias-sepa-andorra/#:~:text=,processed%20the%20next%20business%20day), SDD offers convenience and reliability for both payers and billers in Andorra’s euro-based economy. | H29: https://thepaymentsatlas.com/country/AD
A30: Andorra | B30: AD | D30: Andbank Mobile | F30: https://www.andbank.com | H30: https://thepaymentsatlas.com/country/AD
A31: Andorra | B31: AD | D31: Credit Andorrà Pay | E31: Contactless payments | F31: https://www.creditandorra.ad | H31: https://thepaymentsatlas.com/country/AD
A32: Andorra | B32: AD | D32: International Card Networks (Visa/Mastercard) | E32: Global card schemes used by Andorran banks | F32: https://www.andorra.ad | G32: Andorra has no domestic card scheme; its banks issue internationally accepted cards (Visa, Mastercard, etc.) for both debit and credit. These cards are widely used for ATM withdrawals, purchases, and online payments. Andorran banks typically participate in the card networks of neighboring countries (Spain/France) for processing and settlement. ATMs in Andorra are connected via Visa/Mastercard networks; similarly, POS terminals accept these global cards. Card adoption is high – most adults have at least one debit card. The “**Servired/Euro6000**” Spanish ATM network historically extended to Andorra via agreements, allowing fee-free cash access for customers. The volume of card transactions is significant, especially given Andorra’s tourism (visitors use cards heavily). Andorran-issued cards made **21.2 million** transactions in 2022 (illustrative). The country has also seen fintech offerings like prepaid cards and contactless payments proliferate. Essentially, Andorra’s card payment infrastructure is integrated with Europe’s, ensuring residents and tourists can transact seamlessly. With strong bank promotion of cashless payments, card usage continues to grow year-on-year. | H32: https://thepaymentsatlas.com/country/AD
A33: Andorra | B33: AD | D33: SEPA Instant Credit Transfer (SCT Inst) | E33: Real-time instant payments in euro (via Iberpay) | F33: https://www.europeanpaymentscouncil.eu/what-we-do/sepa-instant-credit-transfer | G33: In 2023, Andorra’s three main banks (Crèdit Andorrà, MoraBanc, Andbank) connected to the Spanish Iberpay instant payments system to enable SEPA Instant transfers (https://www.iberpay.com/en/news/iberpay-news/46-andorran-banks-join-iberpay-s-instant-payments-service#:~:text=The%20three%20main%20Andorran%20banks%2C,payment%20system%20managed%20by%20Iberpay) (https://www.iberpay.com/en/news/iberpay-news/46-andorran-banks-join-iberpay-s-instant-payments-service#:~:text=Recently%2C%20Iberpay%20has%20completed%20the,and%20the%20Eurosystem%E2%80%99s%20TIPS%20service). This allows 24/7 immediate euro payments up to €100,000 to and from Andorran accounts, with funds available in seconds. Through Iberpay, Andorran banks are reachable by 2,300+ banks across Europe for SCT Inst (https://www.iberpay.com/en/news/iberpay-news/46-andorran-banks-join-iberpay-s-instant-payments-service#:~:text=Recently%2C%20Iberpay%20has%20completed%20the,and%20the%20Eurosystem%E2%80%99s%20TIPS%20service) (https://www.iberpay.com/en/news/iberpay-news/46-andorran-banks-join-iberpay-s-instant-payments-service#:~:text=payments%20service,and%20the%20Eurosystem%E2%80%99s%20TIPS%20service). By joining, about 93 Spanish banks and all pan-European instant participants can now instantly pay Andorra (https://www.iberpay.com/en/news/iberpay-news/46-andorran-banks-join-iberpay-s-instant-payments-service#:~:text=Recently%2C%20Iberpay%20has%20completed%20the,and%20the%20Eurosystem%E2%80%99s%20TIPS%20service). Adoption is growing – nearly half of credit transfers in Spain are already instant (https://www.iberpay.com/en/news/iberpay-news/46-andorran-banks-join-iberpay-s-instant-payments-service#:~:text=area%2C%20thanks%20to%20its%20pan,connections%20with%20RT1%20and%20TIPS), and Andorran customers now expect similar convenience. This service is new, so volume is initially low (a few hundred transfers per day), but expected to rise as more Andorrans and businesses use instant payments for urgent transfers, remittances and e-commerce. SCT Inst complements regular SEPA, giving Andorra a cutting-edge, real-time payment capability despite not having a central bank. | H33: https://thepaymentsatlas.com/country/AD
A34: Andorra | B34: AD | D34: Iberpay Instant Payments (SCT Inst) | E34: Crèdit Andorrà, MoraBanc and Andbank connected June 2023; limits €100k within 10 s. | F34: https://www.iberpay.es | H34: https://thepaymentsatlas.com/country/AD
A35: Andorra | B35: AD | D35: PSA/Worldline ACH Clearing | E35: Andorran payments cleared via Payment Services Austria’s mass-payments platform under SEPA rules. | F35: https://www.psa.at | H35: https://thepaymentsatlas.com/country/AD
A36: Andorra | B36: AD | D36: TARGET/T2 via Banco de España | E36: Since 2021 the Institut Nacional Andorrà de Finances (INAF) connects local banks to T2 through Spain; enables high-value euro settlement. | F36: https://inaf.ad | H36: https://thepaymentsatlas.com/country/AD
A37: Andorra | B37: AD | D37: TARGET2 (via Banco de España) | H37: https://thepaymentsatlas.com/country/AD
A38: Angola | B38: AO | D38: STC (Sistema de Transferências a Crédito) | E38: Bulk electronic credit transfer system (ACH) | F38: https://www.emis.ao | G38: STC is Angola’s automated clearing house for domestic credit transfers in kwanza. Operated by **EMIS** (Empresa Interbancária de Serviços) under oversight of BNA, STC processes batched interbank transfers such as payroll, vendor payments, and other low-value credits (https://emis.ao/#:~:text=Sistema%20de%20transfer%C3%AAncias%20a%20cr%C3%A9dito) (https://emis.ao/#:~:text=O%20STC%20%C3%A9%20o%20sistema,por%20opera%C3%A7%C3%A3o%20fixado%20pelo%20BNA). It runs two clearing sessions per day, netting transactions and sending the net settlement to SPTR for final settlement (https://emis.ao/#:~:text=Sistema%20de%20transfer%C3%AAncias%20a%20cr%C3%A9dito) (https://emis.ao/#:~:text=financeira%20do%20Benefici%C3%A1rio,por%20opera%C3%A7%C3%A3o%20fixado%20pelo%20BNA). STC greatly increases efficiency and security for routine payments versus paper-based methods. In 2022, STC handled about **4.76 million** credit transfers (https://emis.ao/#:~:text=Sistema%20de%20Transfer%C3%AAncias). Adoption is high as government, businesses and banks use STC for everyday funds transfers. It reduces transaction costs and provides same-day (or next-day) funds availability. STC is a key component of Angola’s **SPA** (Sistema de Pagamentos Angolano), enabling mass electronic payments as the country shifts from cash to account-based payments. | H38: https://thepaymentsatlas.com/country/AO
A39: Angola | B39: AO | D39: Direct Debit System (Débitos Diretos) | E39: Automated direct debit service for recurring payments | F39: https://www.emis.ao | G39: Launched in 2021, the Sistema de Débitos Directos is Angola’s interbank direct debit mechanism, allowing billers to pull payments from customers’ bank accounts with mandate authorization (https://emis.ao/#:~:text=Image%3A%201400X1200%20Site%20Com%20Frame,SDD). It was developed to modernize recurring payments like utility bills, insurance premiums, and loan repayments. Under this system, customers sign a direct debit mandate with the service provider, and EMIS facilitates the automated debiting through participating banks. The direct debit system complements the credit transfer and card systems, providing convenience for regular obligations. Its adoption is gradually increasing as more billers join and customer trust builds. In a country where many bills were paid in cash or in person, direct debits are a leap in banking convenience and financial inclusion. By consolidating routine payments, it also encourages more people to maintain bank accounts. The service is expected to reach significant volume as major utilities and telecoms migrate customers to direct debit over time. | H39: https://thepaymentsatlas.com/country/AO
A40: Angola | B40: AO | D40: Multicaixa | E40: National payment network | F40: https://www.emis.africa/company/emolumento-sociedade-de-pagamentos-sa | H40: https://thepaymentsatlas.com/country/AO
...

Sheet Países
A1: País | B1: Código | C1: Região | D1: Sistemas registados (segundo o site) | E1: Sistemas extraídos | F1: Resumo do site | G1: Página no Atlas
A2: Afghanistan | B2: AF | D2: 9 | E2: =COUNTIF(Sistemas!$B:$B,B2) | G2: https://thepaymentsatlas.com/country/AF
A3: Albania | B3: AL | D3: 7 | E3: =COUNTIF(Sistemas!$B:$B,B3) | G3: https://thepaymentsatlas.com/country/AL
A4: Algeria | B4: DZ | D4: 10 | E4: =COUNTIF(Sistemas!$B:$B,B4) | G4: https://thepaymentsatlas.com/country/DZ
A5: Andorra | B5: AD | D5: 10 | E5: =COUNTIF(Sistemas!$B:$B,B5) | G5: https://thepaymentsatlas.com/country/AD
A6: Angola | B6: AO | D6: 14 | E6: =COUNTIF(Sistemas!$B:$B,B6) | G6: https://thepaymentsatlas.com/country/AO
A7: Antigua and Barbuda | B7: AG | D7: 5 | E7: =COUNTIF(Sistemas!$B:$B,B7) | G7: https://thepaymentsatlas.com/country/AG
A8: Argentina | B8: AR | D8: 14 | E8: =COUNTIF(Sistemas!$B:$B,B8) | G8: https://thepaymentsatlas.com/country/AR
A9: Armenia | B9: AM | D9: 12 | E9: =COUNTIF(Sistemas!$B:$B,B9) | G9: https://thepaymentsatlas.com/country/AM
A10: Australia | B10: AU | D10: 14 | E10: =COUNTIF(Sistemas!$B:$B,B10) | G10: https://thepaymentsatlas.com/country/AU
A11: Austria | B11: AT | D11: 16 | E11: =COUNTIF(Sistemas!$B:$B,B11) | G11: https://thepaymentsatlas.com/country/AT
A12: Azerbaijan | B12: AZ | D12: 13 | E12: =COUNTIF(Sistemas!$B:$B,B12) | G12: https://thepaymentsatlas.com/country/AZ
A13: Bahamas | B13: BS | D13: 11 | E13: =COUNTIF(Sistemas!$B:$B,B13) | G13: https://thepaymentsatlas.com/country/BS
... A198: Zimbabwe | B198: ZW | D198: 10 | E198: =COUNTIF(Sistemas!$B:$B,B198) | G198: https://thepaymentsatlas.com/country/ZW

Sheet Notas
A1: Fonte | B1: The Payments Atlas — https://thepaymentsatlas.com
A2: Data da extração | B2: 2026-10-30
A3: Conteúdo | B3: Folha 'Sistemas' = uma linha por sistema listado em 'Payment Systems' de cada país.
A4: Conferência | B4: Na folha 'Países', compare 'registados' com 'extraídos'. Diferenças indicam itens por rever.
A5: Referências [n] | B5: As notas de rodapé do tipo [107] foram removidas das descrições.
A6: Direitos | B6: Os dados pertencem ao The Payments Atlas; confirme os termos de uso antes de redistribuir.
